WARNING  urllib3.connectionpool:connectionpool.py:870 Retrying (Retry(total=2, connect=None, read=None, redirect=None, status=None)) after connection broken by 'NewConnectionError('<urllib3.connection.HTTPConnection object at 0x7fb06c76f310>: Failed to establish a new connection: [Errno 111] Connection refused')': /session/e97ec5c2-d728-43f5-be7d-e260897397e9
WARNING  urllib3.connectionpool:connectionpool.py:870 Retrying (Retry(total=1, connect=None, read=None, redirect=None, status=None)) after connection broken by 'NewConnectionError('<urllib3.connection.HTTPConnection object at 0x7fb06c76f280>: Failed to establish a new connection: [Errno 111] Connection refused')': /session/e97ec5c2-d728-43f5-be7d-e260897397e9
WARNING  urllib3.connectionpool:connectionpool.py:870 Retrying (Retry(total=0, connect=None, read=None, redirect=None, status=None)) after connection broken by 'NewConnectionError('<urllib3.connection.HTTPConnection object at 0x7fb06c76f160>: Failed to establish a new connection: [Errno 111] Connection refused')': /session/e97ec5c2-d728-43f5-be7d-e260897397e9