WARNING  urllib3.connectionpool:connectionpool.py:870 Retrying (Retry(total=2, connect=None, read=None, redirect=None, status=None)) after connection broken by 'NewConnectionError('<urllib3.connection.HTTPConnection object at 0x7f406585e020>: Failed to establish a new connection: [Errno 111] Connection refused')': /session/13152ba2-eab4-4820-a89a-81d969bc43ef
WARNING  urllib3.connectionpool:connectionpool.py:870 Retrying (Retry(total=1, connect=None, read=None, redirect=None, status=None)) after connection broken by 'NewConnectionError('<urllib3.connection.HTTPConnection object at 0x7f406585dd20>: Failed to establish a new connection: [Errno 111] Connection refused')': /session/13152ba2-eab4-4820-a89a-81d969bc43ef
WARNING  urllib3.connectionpool:connectionpool.py:870 Retrying (Retry(total=0, connect=None, read=None, redirect=None, status=None)) after connection broken by 'NewConnectionError('<urllib3.connection.HTTPConnection object at 0x7f406585e380>: Failed to establish a new connection: [Errno 111] Connection refused')': /session/13152ba2-eab4-4820-a89a-81d969bc43ef