WARNING  urllib3.connectionpool:connectionpool.py:870 Retrying (Retry(total=2, connect=None, read=None, redirect=None, status=None)) after connection broken by 'NewConnectionError('<urllib3.connection.HTTPConnection object at 0x7fc2497dd6c0>: Failed to establish a new connection: [Errno 111] Connection refused')': /session/6ee39299-e93f-4e34-b074-b0fb89a4fe68
WARNING  urllib3.connectionpool:connectionpool.py:870 Retrying (Retry(total=1, connect=None, read=None, redirect=None, status=None)) after connection broken by 'NewConnectionError('<urllib3.connection.HTTPConnection object at 0x7fc2497ddde0>: Failed to establish a new connection: [Errno 111] Connection refused')': /session/6ee39299-e93f-4e34-b074-b0fb89a4fe68
WARNING  urllib3.connectionpool:connectionpool.py:870 Retrying (Retry(total=0, connect=None, read=None, redirect=None, status=None)) after connection broken by 'NewConnectionError('<urllib3.connection.HTTPConnection object at 0x7fc2497dcf40>: Failed to establish a new connection: [Errno 111] Connection refused')': /session/6ee39299-e93f-4e34-b074-b0fb89a4fe68