WARNING  urllib3.connectionpool:connectionpool.py:870 Retrying (Retry(total=2, connect=None, read=None, redirect=None, status=None)) after connection broken by 'NewConnectionError('<urllib3.connection.HTTPConnection object at 0x7fdd6210b460>: Failed to establish a new connection: [Errno 111] Connection refused')': /session/514f157b-f714-4d23-aa43-bfc8ba9c4448
WARNING  urllib3.connectionpool:connectionpool.py:870 Retrying (Retry(total=1, connect=None, read=None, redirect=None, status=None)) after connection broken by 'NewConnectionError('<urllib3.connection.HTTPConnection object at 0x7fdd6210a9b0>: Failed to establish a new connection: [Errno 111] Connection refused')': /session/514f157b-f714-4d23-aa43-bfc8ba9c4448
WARNING  urllib3.connectionpool:connectionpool.py:870 Retrying (Retry(total=0, connect=None, read=None, redirect=None, status=None)) after connection broken by 'NewConnectionError('<urllib3.connection.HTTPConnection object at 0x7fdd6210b1c0>: Failed to establish a new connection: [Errno 111] Connection refused')': /session/514f157b-f714-4d23-aa43-bfc8ba9c4448