WARNING  urllib3.connectionpool:connectionpool.py:870 Retrying (Retry(total=2, connect=None, read=None, redirect=None, status=None)) after connection broken by 'NewConnectionError('<urllib3.connection.HTTPConnection object at 0x7fa1cbf89ae0>: Failed to establish a new connection: [Errno 111] Connection refused')': /session/99c12c48-9836-4297-996c-83836189922e
WARNING  urllib3.connectionpool:connectionpool.py:870 Retrying (Retry(total=1, connect=None, read=None, redirect=None, status=None)) after connection broken by 'NewConnectionError('<urllib3.connection.HTTPConnection object at 0x7fa1cbf898d0>: Failed to establish a new connection: [Errno 111] Connection refused')': /session/99c12c48-9836-4297-996c-83836189922e
WARNING  urllib3.connectionpool:connectionpool.py:870 Retrying (Retry(total=0, connect=None, read=None, redirect=None, status=None)) after connection broken by 'NewConnectionError('<urllib3.connection.HTTPConnection object at 0x7fa1cbf8a980>: Failed to establish a new connection: [Errno 111] Connection refused')': /session/99c12c48-9836-4297-996c-83836189922e