WARNING  urllib3.connectionpool:connectionpool.py:870 Retrying (Retry(total=2, connect=None, read=None, redirect=None, status=None)) after connection broken by 'NewConnectionError('<urllib3.connection.HTTPConnection object at 0x7f8084233310>: Failed to establish a new connection: [Errno 111] Connection refused')': /session/e54c515f-2c71-41b7-83bd-b3a1c418cf41
WARNING  urllib3.connectionpool:connectionpool.py:870 Retrying (Retry(total=1, connect=None, read=None, redirect=None, status=None)) after connection broken by 'NewConnectionError('<urllib3.connection.HTTPConnection object at 0x7f8084231870>: Failed to establish a new connection: [Errno 111] Connection refused')': /session/e54c515f-2c71-41b7-83bd-b3a1c418cf41
WARNING  urllib3.connectionpool:connectionpool.py:870 Retrying (Retry(total=0, connect=None, read=None, redirect=None, status=None)) after connection broken by 'NewConnectionError('<urllib3.connection.HTTPConnection object at 0x7f80842338e0>: Failed to establish a new connection: [Errno 111] Connection refused')': /session/e54c515f-2c71-41b7-83bd-b3a1c418cf41