WARNING  urllib3.connectionpool:connectionpool.py:870 Retrying (Retry(total=2, connect=None, read=None, redirect=None, status=None)) after connection broken by 'NewConnectionError('<urllib3.connection.HTTPConnection object at 0x7fa117c91570>: Failed to establish a new connection: [Errno 111] Connection refused')': /session/379543bd-e6ce-4eb0-8618-2a61152716d8
WARNING  urllib3.connectionpool:connectionpool.py:870 Retrying (Retry(total=1, connect=None, read=None, redirect=None, status=None)) after connection broken by 'NewConnectionError('<urllib3.connection.HTTPConnection object at 0x7fa117c91660>: Failed to establish a new connection: [Errno 111] Connection refused')': /session/379543bd-e6ce-4eb0-8618-2a61152716d8
WARNING  urllib3.connectionpool:connectionpool.py:870 Retrying (Retry(total=0, connect=None, read=None, redirect=None, status=None)) after connection broken by 'NewConnectionError('<urllib3.connection.HTTPConnection object at 0x7fa117c928c0>: Failed to establish a new connection: [Errno 111] Connection refused')': /session/379543bd-e6ce-4eb0-8618-2a61152716d8