WARNING  urllib3.connectionpool:connectionpool.py:870 Retrying (Retry(total=2, connect=None, read=None, redirect=None, status=None)) after connection broken by 'NewConnectionError('<urllib3.connection.HTTPConnection object at 0x7fcdd98bb490>: Failed to establish a new connection: [Errno 111] Connection refused')': /session/9627fb42-fc35-45c5-93e4-fe8f95205190
WARNING  urllib3.connectionpool:connectionpool.py:870 Retrying (Retry(total=1, connect=None, read=None, redirect=None, status=None)) after connection broken by 'NewConnectionError('<urllib3.connection.HTTPConnection object at 0x7fcdd98bb280>: Failed to establish a new connection: [Errno 111] Connection refused')': /session/9627fb42-fc35-45c5-93e4-fe8f95205190
WARNING  urllib3.connectionpool:connectionpool.py:870 Retrying (Retry(total=0, connect=None, read=None, redirect=None, status=None)) after connection broken by 'NewConnectionError('<urllib3.connection.HTTPConnection object at 0x7fcdd98bb670>: Failed to establish a new connection: [Errno 111] Connection refused')': /session/9627fb42-fc35-45c5-93e4-fe8f95205190