WARNING  urllib3.connectionpool:connectionpool.py:870 Retrying (Retry(total=2, connect=None, read=None, redirect=None, status=None)) after connection broken by 'NewConnectionError('<urllib3.connection.HTTPConnection object at 0x7fb4bc0fb3a0>: Failed to establish a new connection: [Errno 111] Connection refused')': /session/327103c4-dbda-4251-a807-0ad6cff88081
WARNING  urllib3.connectionpool:connectionpool.py:870 Retrying (Retry(total=1, connect=None, read=None, redirect=None, status=None)) after connection broken by 'NewConnectionError('<urllib3.connection.HTTPConnection object at 0x7fb4bc0fb1f0>: Failed to establish a new connection: [Errno 111] Connection refused')': /session/327103c4-dbda-4251-a807-0ad6cff88081
WARNING  urllib3.connectionpool:connectionpool.py:870 Retrying (Retry(total=0, connect=None, read=None, redirect=None, status=None)) after connection broken by 'NewConnectionError('<urllib3.connection.HTTPConnection object at 0x7fb4bc0fa980>: Failed to establish a new connection: [Errno 111] Connection refused')': /session/327103c4-dbda-4251-a807-0ad6cff88081