WARNING  urllib3.connectionpool:connectionpool.py:870 Retrying (Retry(total=2, connect=None, read=None, redirect=None, status=None)) after connection broken by 'NewConnectionError('<urllib3.connection.HTTPConnection object at 0x7efeb867ffd0>: Failed to establish a new connection: [Errno 111] Connection refused')': /session/3171a1d1-0e5b-411f-86da-548d321a0cf4
WARNING  urllib3.connectionpool:connectionpool.py:870 Retrying (Retry(total=1, connect=None, read=None, redirect=None, status=None)) after connection broken by 'NewConnectionError('<urllib3.connection.HTTPConnection object at 0x7efeb867d180>: Failed to establish a new connection: [Errno 111] Connection refused')': /session/3171a1d1-0e5b-411f-86da-548d321a0cf4
WARNING  urllib3.connectionpool:connectionpool.py:870 Retrying (Retry(total=0, connect=None, read=None, redirect=None, status=None)) after connection broken by 'NewConnectionError('<urllib3.connection.HTTPConnection object at 0x7efeb867f4f0>: Failed to establish a new connection: [Errno 111] Connection refused')': /session/3171a1d1-0e5b-411f-86da-548d321a0cf4