WARNING  urllib3.connectionpool:connectionpool.py:870 Retrying (Retry(total=2, connect=None, read=None, redirect=None, status=None)) after connection broken by 'NewConnectionError('<urllib3.connection.HTTPConnection object at 0x7f9b382cf3d0>: Failed to establish a new connection: [Errno 111] Connection refused')': /session/1f44af8a-273c-4afc-b0cc-7ab1690810db
WARNING  urllib3.connectionpool:connectionpool.py:870 Retrying (Retry(total=1, connect=None, read=None, redirect=None, status=None)) after connection broken by 'NewConnectionError('<urllib3.connection.HTTPConnection object at 0x7f9b382cf0d0>: Failed to establish a new connection: [Errno 111] Connection refused')': /session/1f44af8a-273c-4afc-b0cc-7ab1690810db
WARNING  urllib3.connectionpool:connectionpool.py:870 Retrying (Retry(total=0, connect=None, read=None, redirect=None, status=None)) after connection broken by 'NewConnectionError('<urllib3.connection.HTTPConnection object at 0x7f9b382cf670>: Failed to establish a new connection: [Errno 111] Connection refused')': /session/1f44af8a-273c-4afc-b0cc-7ab1690810db