WARNING  urllib3.connectionpool:connectionpool.py:870 Retrying (Retry(total=2, connect=None, read=None, redirect=None, status=None)) after connection broken by 'NewConnectionError('<urllib3.connection.HTTPConnection object at 0x7fa30a674ca0>: Failed to establish a new connection: [Errno 111] Connection refused')': /session/8e252f3a-cb56-427b-9730-5a44d59d81cd
WARNING  urllib3.connectionpool:connectionpool.py:870 Retrying (Retry(total=1, connect=None, read=None, redirect=None, status=None)) after connection broken by 'NewConnectionError('<urllib3.connection.HTTPConnection object at 0x7fa30a675870>: Failed to establish a new connection: [Errno 111] Connection refused')': /session/8e252f3a-cb56-427b-9730-5a44d59d81cd
WARNING  urllib3.connectionpool:connectionpool.py:870 Retrying (Retry(total=0, connect=None, read=None, redirect=None, status=None)) after connection broken by 'NewConnectionError('<urllib3.connection.HTTPConnection object at 0x7fa30a674130>: Failed to establish a new connection: [Errno 111] Connection refused')': /session/8e252f3a-cb56-427b-9730-5a44d59d81cd