WARNING  urllib3.connectionpool:connectionpool.py:870 Retrying (Retry(total=2, connect=None, read=None, redirect=None, status=None)) after connection broken by 'NewConnectionError('<urllib3.connection.HTTPConnection object at 0x7f5294479690>: Failed to establish a new connection: [Errno 111] Connection refused')': /session/22512601-bd3c-417b-960c-0781b0d0ebb8
WARNING  urllib3.connectionpool:connectionpool.py:870 Retrying (Retry(total=1, connect=None, read=None, redirect=None, status=None)) after connection broken by 'NewConnectionError('<urllib3.connection.HTTPConnection object at 0x7f5294479780>: Failed to establish a new connection: [Errno 111] Connection refused')': /session/22512601-bd3c-417b-960c-0781b0d0ebb8
WARNING  urllib3.connectionpool:connectionpool.py:870 Retrying (Retry(total=0, connect=None, read=None, redirect=None, status=None)) after connection broken by 'NewConnectionError('<urllib3.connection.HTTPConnection object at 0x7f529447bca0>: Failed to establish a new connection: [Errno 111] Connection refused')': /session/22512601-bd3c-417b-960c-0781b0d0ebb8