WARNING  urllib3.connectionpool:connectionpool.py:870 Retrying (Retry(total=2, connect=None, read=None, redirect=None, status=None)) after connection broken by 'NewConnectionError('<urllib3.connection.HTTPConnection object at 0x7f7aaf09b490>: Failed to establish a new connection: [Errno 111] Connection refused')': /session/63749907-67ba-41e1-ba61-42737d42d0cb
WARNING  urllib3.connectionpool:connectionpool.py:870 Retrying (Retry(total=1, connect=None, read=None, redirect=None, status=None)) after connection broken by 'NewConnectionError('<urllib3.connection.HTTPConnection object at 0x7f7aaf09b370>: Failed to establish a new connection: [Errno 111] Connection refused')': /session/63749907-67ba-41e1-ba61-42737d42d0cb
WARNING  urllib3.connectionpool:connectionpool.py:870 Retrying (Retry(total=0, connect=None, read=None, redirect=None, status=None)) after connection broken by 'NewConnectionError('<urllib3.connection.HTTPConnection object at 0x7f7aaf09b640>: Failed to establish a new connection: [Errno 111] Connection refused')': /session/63749907-67ba-41e1-ba61-42737d42d0cb