WARNING  urllib3.connectionpool:connectionpool.py:870 Retrying (Retry(total=2, connect=None, read=None, redirect=None, status=None)) after connection broken by 'NewConnectionError('<urllib3.connection.HTTPConnection object at 0x7fdd6220bb80>: Failed to establish a new connection: [Errno 111] Connection refused')': /session/8562bce9-1db4-46b7-b45f-083236d71b64
WARNING  urllib3.connectionpool:connectionpool.py:870 Retrying (Retry(total=1, connect=None, read=None, redirect=None, status=None)) after connection broken by 'NewConnectionError('<urllib3.connection.HTTPConnection object at 0x7fdd6220bc10>: Failed to establish a new connection: [Errno 111] Connection refused')': /session/8562bce9-1db4-46b7-b45f-083236d71b64
WARNING  urllib3.connectionpool:connectionpool.py:870 Retrying (Retry(total=0, connect=None, read=None, redirect=None, status=None)) after connection broken by 'NewConnectionError('<urllib3.connection.HTTPConnection object at 0x7fdd62335e70>: Failed to establish a new connection: [Errno 111] Connection refused')': /session/8562bce9-1db4-46b7-b45f-083236d71b64