WARNING  urllib3.connectionpool:connectionpool.py:870 Retrying (Retry(total=2, connect=None, read=None, redirect=None, status=None)) after connection broken by 'NewConnectionError('<urllib3.connection.HTTPConnection object at 0x7fb4bc278df0>: Failed to establish a new connection: [Errno 111] Connection refused')': /session/951731ad-54a3-4a80-9636-6c652a9f8831
WARNING  urllib3.connectionpool:connectionpool.py:870 Retrying (Retry(total=1, connect=None, read=None, redirect=None, status=None)) after connection broken by 'NewConnectionError('<urllib3.connection.HTTPConnection object at 0x7fb4bc278490>: Failed to establish a new connection: [Errno 111] Connection refused')': /session/951731ad-54a3-4a80-9636-6c652a9f8831
WARNING  urllib3.connectionpool:connectionpool.py:870 Retrying (Retry(total=0, connect=None, read=None, redirect=None, status=None)) after connection broken by 'NewConnectionError('<urllib3.connection.HTTPConnection object at 0x7fb4bc278400>: Failed to establish a new connection: [Errno 111] Connection refused')': /session/951731ad-54a3-4a80-9636-6c652a9f8831