WARNING  urllib3.connectionpool:connectionpool.py:870 Retrying (Retry(total=2, connect=None, read=None, redirect=None, status=None)) after connection broken by 'NewConnectionError('<urllib3.connection.HTTPConnection object at 0x7fc24965b580>: Failed to establish a new connection: [Errno 111] Connection refused')': /session/ca93dc3b-3fc6-4d26-a57c-52b096f6942f
WARNING  urllib3.connectionpool:connectionpool.py:870 Retrying (Retry(total=1, connect=None, read=None, redirect=None, status=None)) after connection broken by 'NewConnectionError('<urllib3.connection.HTTPConnection object at 0x7fc24965b280>: Failed to establish a new connection: [Errno 111] Connection refused')': /session/ca93dc3b-3fc6-4d26-a57c-52b096f6942f
WARNING  urllib3.connectionpool:connectionpool.py:870 Retrying (Retry(total=0, connect=None, read=None, redirect=None, status=None)) after connection broken by 'NewConnectionError('<urllib3.connection.HTTPConnection object at 0x7fc24965b820>: Failed to establish a new connection: [Errno 111] Connection refused')': /session/ca93dc3b-3fc6-4d26-a57c-52b096f6942f