WARNING  urllib3.connectionpool:connectionpool.py:870 Retrying (Retry(total=2, connect=None, read=None, redirect=None, status=None)) after connection broken by 'NewConnectionError('<urllib3.connection.HTTPConnection object at 0x7f0833f075e0>: Failed to establish a new connection: [Errno 111] Connection refused')': /session/3bce77ae-a867-4211-89fd-f78e861e6612
WARNING  urllib3.connectionpool:connectionpool.py:870 Retrying (Retry(total=1, connect=None, read=None, redirect=None, status=None)) after connection broken by 'NewConnectionError('<urllib3.connection.HTTPConnection object at 0x7f0833f06b30>: Failed to establish a new connection: [Errno 111] Connection refused')': /session/3bce77ae-a867-4211-89fd-f78e861e6612
WARNING  urllib3.connectionpool:connectionpool.py:870 Retrying (Retry(total=0, connect=None, read=None, redirect=None, status=None)) after connection broken by 'NewConnectionError('<urllib3.connection.HTTPConnection object at 0x7f0833f07340>: Failed to establish a new connection: [Errno 111] Connection refused')': /session/3bce77ae-a867-4211-89fd-f78e861e6612