WARNING  urllib3.connectionpool:connectionpool.py:870 Retrying (Retry(total=2, connect=None, read=None, redirect=None, status=None)) after connection broken by 'NewConnectionError('<urllib3.connection.HTTPConnection object at 0x7f7e285c96c0>: Failed to establish a new connection: [Errno 111] Connection refused')': /session/83739918-a988-4fe3-8fc1-1b8958d676d9
WARNING  urllib3.connectionpool:connectionpool.py:870 Retrying (Retry(total=1, connect=None, read=None, redirect=None, status=None)) after connection broken by 'NewConnectionError('<urllib3.connection.HTTPConnection object at 0x7f7e285c98a0>: Failed to establish a new connection: [Errno 111] Connection refused')': /session/83739918-a988-4fe3-8fc1-1b8958d676d9
WARNING  urllib3.connectionpool:connectionpool.py:870 Retrying (Retry(total=0, connect=None, read=None, redirect=None, status=None)) after connection broken by 'NewConnectionError('<urllib3.connection.HTTPConnection object at 0x7f7e285c87f0>: Failed to establish a new connection: [Errno 111] Connection refused')': /session/83739918-a988-4fe3-8fc1-1b8958d676d9