WARNING  urllib3.connectionpool:connectionpool.py:870 Retrying (Retry(total=2, connect=None, read=None, redirect=None, status=None)) after connection broken by 'NewConnectionError('<urllib3.connection.HTTPConnection object at 0x7f193729f3d0>: Failed to establish a new connection: [Errno 111] Connection refused')': /session/3750bc27-9b50-410d-b923-f11c5f6d7bd8
WARNING  urllib3.connectionpool:connectionpool.py:870 Retrying (Retry(total=1, connect=None, read=None, redirect=None, status=None)) after connection broken by 'NewConnectionError('<urllib3.connection.HTTPConnection object at 0x7f193729f220>: Failed to establish a new connection: [Errno 111] Connection refused')': /session/3750bc27-9b50-410d-b923-f11c5f6d7bd8
WARNING  urllib3.connectionpool:connectionpool.py:870 Retrying (Retry(total=0, connect=None, read=None, redirect=None, status=None)) after connection broken by 'NewConnectionError('<urllib3.connection.HTTPConnection object at 0x7f193729efb0>: Failed to establish a new connection: [Errno 111] Connection refused')': /session/3750bc27-9b50-410d-b923-f11c5f6d7bd8