WARNING  urllib3.connectionpool:connectionpool.py:870 Retrying (Retry(total=2, connect=None, read=None, redirect=None, status=None)) after connection broken by 'NewConnectionError('<urllib3.connection.HTTPConnection object at 0x7fd0889234c0>: Failed to establish a new connection: [Errno 111] Connection refused')': /session/012d2506-bc73-4a22-a659-f35c466b8504
WARNING  urllib3.connectionpool:connectionpool.py:870 Retrying (Retry(total=1, connect=None, read=None, redirect=None, status=None)) after connection broken by 'NewConnectionError('<urllib3.connection.HTTPConnection object at 0x7fd088923310>: Failed to establish a new connection: [Errno 111] Connection refused')': /session/012d2506-bc73-4a22-a659-f35c466b8504
WARNING  urllib3.connectionpool:connectionpool.py:870 Retrying (Retry(total=0, connect=None, read=None, redirect=None, status=None)) after connection broken by 'NewConnectionError('<urllib3.connection.HTTPConnection object at 0x7fd088923580>: Failed to establish a new connection: [Errno 111] Connection refused')': /session/012d2506-bc73-4a22-a659-f35c466b8504