WARNING  urllib3.connectionpool:connectionpool.py:870 Retrying (Retry(total=2, connect=None, read=None, redirect=None, status=None)) after connection broken by 'NewConnectionError('<urllib3.connection.HTTPConnection object at 0x7f9ee7967580>: Failed to establish a new connection: [Errno 111] Connection refused')': /session/fd788c9b-0bc3-40a6-8c6b-de88e38adfd6
WARNING  urllib3.connectionpool:connectionpool.py:870 Retrying (Retry(total=1, connect=None, read=None, redirect=None, status=None)) after connection broken by 'NewConnectionError('<urllib3.connection.HTTPConnection object at 0x7f9ee7967370>: Failed to establish a new connection: [Errno 111] Connection refused')': /session/fd788c9b-0bc3-40a6-8c6b-de88e38adfd6
WARNING  urllib3.connectionpool:connectionpool.py:870 Retrying (Retry(total=0, connect=None, read=None, redirect=None, status=None)) after connection broken by 'NewConnectionError('<urllib3.connection.HTTPConnection object at 0x7f9ee7967190>: Failed to establish a new connection: [Errno 111] Connection refused')': /session/fd788c9b-0bc3-40a6-8c6b-de88e38adfd6