WARNING  urllib3.connectionpool:connectionpool.py:870 Retrying (Retry(total=2, connect=None, read=None, redirect=None, status=None)) after connection broken by 'NewConnectionError('<urllib3.connection.HTTPConnection object at 0x7f35bc43b460>: Failed to establish a new connection: [Errno 111] Connection refused')': /session/d5921912-c0d4-4998-8f54-3b03f8f51f36
WARNING  urllib3.connectionpool:connectionpool.py:870 Retrying (Retry(total=1, connect=None, read=None, redirect=None, status=None)) after connection broken by 'NewConnectionError('<urllib3.connection.HTTPConnection object at 0x7f35bc4399c0>: Failed to establish a new connection: [Errno 111] Connection refused')': /session/d5921912-c0d4-4998-8f54-3b03f8f51f36
WARNING  urllib3.connectionpool:connectionpool.py:870 Retrying (Retry(total=0, connect=None, read=None, redirect=None, status=None)) after connection broken by 'NewConnectionError('<urllib3.connection.HTTPConnection object at 0x7f35bc439720>: Failed to establish a new connection: [Errno 111] Connection refused')': /session/d5921912-c0d4-4998-8f54-3b03f8f51f36