WARNING  urllib3.connectionpool:connectionpool.py:870 Retrying (Retry(total=2, connect=None, read=None, redirect=None, status=None)) after connection broken by 'NewConnectionError('<urllib3.connection.HTTPConnection object at 0x7f69fe52d660>: Failed to establish a new connection: [Errno 111] Connection refused')': /session/ecff9950-47bc-41ef-9d1f-08f7665938f7
WARNING  urllib3.connectionpool:connectionpool.py:870 Retrying (Retry(total=1, connect=None, read=None, redirect=None, status=None)) after connection broken by 'NewConnectionError('<urllib3.connection.HTTPConnection object at 0x7f69fe52d7b0>: Failed to establish a new connection: [Errno 111] Connection refused')': /session/ecff9950-47bc-41ef-9d1f-08f7665938f7
WARNING  urllib3.connectionpool:connectionpool.py:870 Retrying (Retry(total=0, connect=None, read=None, redirect=None, status=None)) after connection broken by 'NewConnectionError('<urllib3.connection.HTTPConnection object at 0x7f69fe52e050>: Failed to establish a new connection: [Errno 111] Connection refused')': /session/ecff9950-47bc-41ef-9d1f-08f7665938f7