WARNING  urllib3.connectionpool:connectionpool.py:870 Retrying (Retry(total=2, connect=None, read=None, redirect=None, status=None)) after connection broken by 'NewConnectionError('<urllib3.connection.HTTPConnection object at 0x7fbda94c20b0>: Failed to establish a new connection: [Errno 111] Connection refused')': /session/9e99ac69-a3ed-458c-9014-2f6f83fafe8e
WARNING  urllib3.connectionpool:connectionpool.py:870 Retrying (Retry(total=1, connect=None, read=None, redirect=None, status=None)) after connection broken by 'NewConnectionError('<urllib3.connection.HTTPConnection object at 0x7fbda94c1e40>: Failed to establish a new connection: [Errno 111] Connection refused')': /session/9e99ac69-a3ed-458c-9014-2f6f83fafe8e
WARNING  urllib3.connectionpool:connectionpool.py:870 Retrying (Retry(total=0, connect=None, read=None, redirect=None, status=None)) after connection broken by 'NewConnectionError('<urllib3.connection.HTTPConnection object at 0x7fbda94c22c0>: Failed to establish a new connection: [Errno 111] Connection refused')': /session/9e99ac69-a3ed-458c-9014-2f6f83fafe8e