WARNING  urllib3.connectionpool:connectionpool.py:870 Retrying (Retry(total=2, connect=None, read=None, redirect=None, status=None)) after connection broken by 'NewConnectionError('<urllib3.connection.HTTPConnection object at 0x7f58a716f460>: Failed to establish a new connection: [Errno 111] Connection refused')': /session/21a2b48d-5a9d-4f4f-8cef-4b8ad2a4d6cd
WARNING  urllib3.connectionpool:connectionpool.py:870 Retrying (Retry(total=1, connect=None, read=None, redirect=None, status=None)) after connection broken by 'NewConnectionError('<urllib3.connection.HTTPConnection object at 0x7f58a716f280>: Failed to establish a new connection: [Errno 111] Connection refused')': /session/21a2b48d-5a9d-4f4f-8cef-4b8ad2a4d6cd
WARNING  urllib3.connectionpool:connectionpool.py:870 Retrying (Retry(total=0, connect=None, read=None, redirect=None, status=None)) after connection broken by 'NewConnectionError('<urllib3.connection.HTTPConnection object at 0x7f58a716f1c0>: Failed to establish a new connection: [Errno 111] Connection refused')': /session/21a2b48d-5a9d-4f4f-8cef-4b8ad2a4d6cd