WARNING  urllib3.connectionpool:connectionpool.py:870 Retrying (Retry(total=2, connect=None, read=None, redirect=None, status=None)) after connection broken by 'NewConnectionError('<urllib3.connection.HTTPConnection object at 0x7f3916526110>: Failed to establish a new connection: [Errno 111] Connection refused')': /session/8de981c0-062a-4309-aa16-2aaeda38d0e5
WARNING  urllib3.connectionpool:connectionpool.py:870 Retrying (Retry(total=1, connect=None, read=None, redirect=None, status=None)) after connection broken by 'NewConnectionError('<urllib3.connection.HTTPConnection object at 0x7f39165258d0>: Failed to establish a new connection: [Errno 111] Connection refused')': /session/8de981c0-062a-4309-aa16-2aaeda38d0e5
WARNING  urllib3.connectionpool:connectionpool.py:870 Retrying (Retry(total=0, connect=None, read=None, redirect=None, status=None)) after connection broken by 'NewConnectionError('<urllib3.connection.HTTPConnection object at 0x7f3916527400>: Failed to establish a new connection: [Errno 111] Connection refused')': /session/8de981c0-062a-4309-aa16-2aaeda38d0e5