WARNING  urllib3.connectionpool:connectionpool.py:870 Retrying (Retry(total=2, connect=None, read=None, redirect=None, status=None)) after connection broken by 'NewConnectionError('<urllib3.connection.HTTPConnection object at 0x7f9b38449570>: Failed to establish a new connection: [Errno 111] Connection refused')': /session/7a50cefb-5a6e-4ce5-8cb5-b3e246aaa477
WARNING  urllib3.connectionpool:connectionpool.py:870 Retrying (Retry(total=1, connect=None, read=None, redirect=None, status=None)) after connection broken by 'NewConnectionError('<urllib3.connection.HTTPConnection object at 0x7f9b384495a0>: Failed to establish a new connection: [Errno 111] Connection refused')': /session/7a50cefb-5a6e-4ce5-8cb5-b3e246aaa477
WARNING  urllib3.connectionpool:connectionpool.py:870 Retrying (Retry(total=0, connect=None, read=None, redirect=None, status=None)) after connection broken by 'NewConnectionError('<urllib3.connection.HTTPConnection object at 0x7f9b384483d0>: Failed to establish a new connection: [Errno 111] Connection refused')': /session/7a50cefb-5a6e-4ce5-8cb5-b3e246aaa477