WARNING  urllib3.connectionpool:connectionpool.py:870 Retrying (Retry(total=2, connect=None, read=None, redirect=None, status=None)) after connection broken by 'NewConnectionError('<urllib3.connection.HTTPConnection object at 0x7fa1cbbe7400>: Failed to establish a new connection: [Errno 111] Connection refused')': /session/26b039fc-caa7-46ea-9017-f14f036c280f
WARNING  urllib3.connectionpool:connectionpool.py:870 Retrying (Retry(total=1, connect=None, read=None, redirect=None, status=None)) after connection broken by 'NewConnectionError('<urllib3.connection.HTTPConnection object at 0x7fa1cbbe71f0>: Failed to establish a new connection: [Errno 111] Connection refused')': /session/26b039fc-caa7-46ea-9017-f14f036c280f
WARNING  urllib3.connectionpool:connectionpool.py:870 Retrying (Retry(total=0, connect=None, read=None, redirect=None, status=None)) after connection broken by 'NewConnectionError('<urllib3.connection.HTTPConnection object at 0x7fa1cbbe75e0>: Failed to establish a new connection: [Errno 111] Connection refused')': /session/26b039fc-caa7-46ea-9017-f14f036c280f