WARNING  urllib3.connectionpool:connectionpool.py:870 Retrying (Retry(total=2, connect=None, read=None, redirect=None, status=None)) after connection broken by 'NewConnectionError('<urllib3.connection.HTTPConnection object at 0x7f13927ab3d0>: Failed to establish a new connection: [Errno 111] Connection refused')': /session/fc5234d3-d423-42ed-847e-2c8701dd1b70
WARNING  urllib3.connectionpool:connectionpool.py:870 Retrying (Retry(total=1, connect=None, read=None, redirect=None, status=None)) after connection broken by 'NewConnectionError('<urllib3.connection.HTTPConnection object at 0x7f13927ab130>: Failed to establish a new connection: [Errno 111] Connection refused')': /session/fc5234d3-d423-42ed-847e-2c8701dd1b70
WARNING  urllib3.connectionpool:connectionpool.py:870 Retrying (Retry(total=0, connect=None, read=None, redirect=None, status=None)) after connection broken by 'NewConnectionError('<urllib3.connection.HTTPConnection object at 0x7f13927ab610>: Failed to establish a new connection: [Errno 111] Connection refused')': /session/fc5234d3-d423-42ed-847e-2c8701dd1b70