WARNING  urllib3.connectionpool:connectionpool.py:870 Retrying (Retry(total=2, connect=None, read=None, redirect=None, status=None)) after connection broken by 'NewConnectionError('<urllib3.connection.HTTPConnection object at 0x7fcdd9a35c90>: Failed to establish a new connection: [Errno 111] Connection refused')': /session/18f64779-4ded-4956-a10d-22d40f2f6bc0
WARNING  urllib3.connectionpool:connectionpool.py:870 Retrying (Retry(total=1, connect=None, read=None, redirect=None, status=None)) after connection broken by 'NewConnectionError('<urllib3.connection.HTTPConnection object at 0x7fcdd9a358a0>: Failed to establish a new connection: [Errno 111] Connection refused')': /session/18f64779-4ded-4956-a10d-22d40f2f6bc0
WARNING  urllib3.connectionpool:connectionpool.py:870 Retrying (Retry(total=0, connect=None, read=None, redirect=None, status=None)) after connection broken by 'NewConnectionError('<urllib3.connection.HTTPConnection object at 0x7fcdd9a37490>: Failed to establish a new connection: [Errno 111] Connection refused')': /session/18f64779-4ded-4956-a10d-22d40f2f6bc0