WARNING  urllib3.connectionpool:connectionpool.py:870 Retrying (Retry(total=2, connect=None, read=None, redirect=None, status=None)) after connection broken by 'NewConnectionError('<urllib3.connection.HTTPConnection object at 0x7f083400ec20>: Failed to establish a new connection: [Errno 111] Connection refused')': /session/112dda43-9a87-48ae-94f6-1cce0f30634c
WARNING  urllib3.connectionpool:connectionpool.py:870 Retrying (Retry(total=1, connect=None, read=None, redirect=None, status=None)) after connection broken by 'NewConnectionError('<urllib3.connection.HTTPConnection object at 0x7f083400e680>: Failed to establish a new connection: [Errno 111] Connection refused')': /session/112dda43-9a87-48ae-94f6-1cce0f30634c
WARNING  urllib3.connectionpool:connectionpool.py:870 Retrying (Retry(total=0, connect=None, read=None, redirect=None, status=None)) after connection broken by 'NewConnectionError('<urllib3.connection.HTTPConnection object at 0x7f083413e6b0>: Failed to establish a new connection: [Errno 111] Connection refused')': /session/112dda43-9a87-48ae-94f6-1cce0f30634c