WARNING  urllib3.connectionpool:connectionpool.py:870 Retrying (Retry(total=2, connect=None, read=None, redirect=None, status=None)) after connection broken by 'NewConnectionError('<urllib3.connection.HTTPConnection object at 0x7fb06c8ed900>: Failed to establish a new connection: [Errno 111] Connection refused')': /session/52dee5f4-27bf-4ce5-81b3-3b3847da98a1
WARNING  urllib3.connectionpool:connectionpool.py:870 Retrying (Retry(total=1, connect=None, read=None, redirect=None, status=None)) after connection broken by 'NewConnectionError('<urllib3.connection.HTTPConnection object at 0x7fb06c8ed7b0>: Failed to establish a new connection: [Errno 111] Connection refused')': /session/52dee5f4-27bf-4ce5-81b3-3b3847da98a1
WARNING  urllib3.connectionpool:connectionpool.py:870 Retrying (Retry(total=0, connect=None, read=None, redirect=None, status=None)) after connection broken by 'NewConnectionError('<urllib3.connection.HTTPConnection object at 0x7fb06c8ecf10>: Failed to establish a new connection: [Errno 111] Connection refused')': /session/52dee5f4-27bf-4ce5-81b3-3b3847da98a1