WARNING  urllib3.connectionpool:connectionpool.py:870 Retrying (Retry(total=2, connect=None, read=None, redirect=None, status=None)) after connection broken by 'NewConnectionError('<urllib3.connection.HTTPConnection object at 0x7f35bc2bf520>: Failed to establish a new connection: [Errno 111] Connection refused')': /session/58dbce9f-4946-4dcd-bc5e-aca8edededc0
WARNING  urllib3.connectionpool:connectionpool.py:870 Retrying (Retry(total=1, connect=None, read=None, redirect=None, status=None)) after connection broken by 'NewConnectionError('<urllib3.connection.HTTPConnection object at 0x7f35bc2bec20>: Failed to establish a new connection: [Errno 111] Connection refused')': /session/58dbce9f-4946-4dcd-bc5e-aca8edededc0
WARNING  urllib3.connectionpool:connectionpool.py:870 Retrying (Retry(total=0, connect=None, read=None, redirect=None, status=None)) after connection broken by 'NewConnectionError('<urllib3.connection.HTTPConnection object at 0x7f35bc2bf130>: Failed to establish a new connection: [Errno 111] Connection refused')': /session/58dbce9f-4946-4dcd-bc5e-aca8edededc0