WARNING  urllib3.connectionpool:connectionpool.py:870 Retrying (Retry(total=2, connect=None, read=None, redirect=None, status=None)) after connection broken by 'NewConnectionError('<urllib3.connection.HTTPConnection object at 0x7f58ccfbfe50>: Failed to establish a new connection: [Errno 111] Connection refused')': /session/18e5681e-1e4f-412c-ba6c-7ba5a6395eb7
WARNING  urllib3.connectionpool:connectionpool.py:870 Retrying (Retry(total=1, connect=None, read=None, redirect=None, status=None)) after connection broken by 'NewConnectionError('<urllib3.connection.HTTPConnection object at 0x7f58ccfbd2d0>: Failed to establish a new connection: [Errno 111] Connection refused')': /session/18e5681e-1e4f-412c-ba6c-7ba5a6395eb7
WARNING  urllib3.connectionpool:connectionpool.py:870 Retrying (Retry(total=0, connect=None, read=None, redirect=None, status=None)) after connection broken by 'NewConnectionError('<urllib3.connection.HTTPConnection object at 0x7f58ccfbc850>: Failed to establish a new connection: [Errno 111] Connection refused')': /session/18e5681e-1e4f-412c-ba6c-7ba5a6395eb7