WARNING  urllib3.connectionpool:connectionpool.py:870 Retrying (Retry(total=2, connect=None, read=None, redirect=None, status=None)) after connection broken by 'NewConnectionError('<urllib3.connection.HTTPConnection object at 0x7f39163ab460>: Failed to establish a new connection: [Errno 111] Connection refused')': /session/6e996b1b-5fb8-4222-a17f-8c0580cf2176
WARNING  urllib3.connectionpool:connectionpool.py:870 Retrying (Retry(total=1, connect=None, read=None, redirect=None, status=None)) after connection broken by 'NewConnectionError('<urllib3.connection.HTTPConnection object at 0x7f39163ab280>: Failed to establish a new connection: [Errno 111] Connection refused')': /session/6e996b1b-5fb8-4222-a17f-8c0580cf2176
WARNING  urllib3.connectionpool:connectionpool.py:870 Retrying (Retry(total=0, connect=None, read=None, redirect=None, status=None)) after connection broken by 'NewConnectionError('<urllib3.connection.HTTPConnection object at 0x7f39163ab670>: Failed to establish a new connection: [Errno 111] Connection refused')': /session/6e996b1b-5fb8-4222-a17f-8c0580cf2176