WARNING  urllib3.connectionpool:connectionpool.py:870 Retrying (Retry(total=2, connect=None, read=None, redirect=None, status=None)) after connection broken by 'NewConnectionError('<urllib3.connection.HTTPConnection object at 0x7f6b86b9f430>: Failed to establish a new connection: [Errno 111] Connection refused')': /session/256ede7d-ee27-45d5-ab40-d0bc1d104bfa
WARNING  urllib3.connectionpool:connectionpool.py:870 Retrying (Retry(total=1, connect=None, read=None, redirect=None, status=None)) after connection broken by 'NewConnectionError('<urllib3.connection.HTTPConnection object at 0x7f6b86b9ef20>: Failed to establish a new connection: [Errno 111] Connection refused')': /session/256ede7d-ee27-45d5-ab40-d0bc1d104bfa
WARNING  urllib3.connectionpool:connectionpool.py:870 Retrying (Retry(total=0, connect=None, read=None, redirect=None, status=None)) after connection broken by 'NewConnectionError('<urllib3.connection.HTTPConnection object at 0x7f6b86b9f040>: Failed to establish a new connection: [Errno 111] Connection refused')': /session/256ede7d-ee27-45d5-ab40-d0bc1d104bfa