WARNING  urllib3.connectionpool:connectionpool.py:870 Retrying (Retry(total=2, connect=None, read=None, redirect=None, status=None)) after connection broken by 'NewConnectionError('<urllib3.connection.HTTPConnection object at 0x7fea59d3f400>: Failed to establish a new connection: [Errno 111] Connection refused')': /session/c9d69c27-5a34-44ae-812c-8ce99fc9a8f0
WARNING  urllib3.connectionpool:connectionpool.py:870 Retrying (Retry(total=1, connect=None, read=None, redirect=None, status=None)) after connection broken by 'NewConnectionError('<urllib3.connection.HTTPConnection object at 0x7fea59d3f220>: Failed to establish a new connection: [Errno 111] Connection refused')': /session/c9d69c27-5a34-44ae-812c-8ce99fc9a8f0
WARNING  urllib3.connectionpool:connectionpool.py:870 Retrying (Retry(total=0, connect=None, read=None, redirect=None, status=None)) after connection broken by 'NewConnectionError('<urllib3.connection.HTTPConnection object at 0x7fea59d3f610>: Failed to establish a new connection: [Errno 111] Connection refused')': /session/c9d69c27-5a34-44ae-812c-8ce99fc9a8f0