WARNING  urllib3.connectionpool:connectionpool.py:870 Retrying (Retry(total=2, connect=None, read=None, redirect=None, status=None)) after connection broken by 'NewConnectionError('<urllib3.connection.HTTPConnection object at 0x7f0516a3da80>: Failed to establish a new connection: [Errno 111] Connection refused')': /session/c613746f-f828-4edf-aa98-af8da122ddb1
WARNING  urllib3.connectionpool:connectionpool.py:870 Retrying (Retry(total=1, connect=None, read=None, redirect=None, status=None)) after connection broken by 'NewConnectionError('<urllib3.connection.HTTPConnection object at 0x7f0516a3da20>: Failed to establish a new connection: [Errno 111] Connection refused')': /session/c613746f-f828-4edf-aa98-af8da122ddb1
WARNING  urllib3.connectionpool:connectionpool.py:870 Retrying (Retry(total=0, connect=None, read=None, redirect=None, status=None)) after connection broken by 'NewConnectionError('<urllib3.connection.HTTPConnection object at 0x7f0516b6a4d0>: Failed to establish a new connection: [Errno 111] Connection refused')': /session/c613746f-f828-4edf-aa98-af8da122ddb1